Workbook

Sheet הגדרות
A1: ספק | B1: ההנחה שלי % | C1: מרווח % | D1: מרווח ₪ קבוע
A2: Royal Canin VET | B2: 0 | C2: 0 | D2: 0
A3: Royal Canin חנויות | B3: 0 | C3: 0 | D3: 0
A4: Hill's Prescription Diet | B4: 0 | C4: 0 | D4: 0
A5: Hill's Science Plan | B5: 0 | C5: 0 | D5: 0
A6: Hill's Vet Essentials | B6: 0 | C6: 0 | D6: 0
A7: VetLife | B7: 0 | C7: 0 | D7: 0
A8: Purina Pro Plan VET | B8: 0 | C8: 0 | D8: 0
A9: פורינה (חנויות) | B9: 0 | C9: 0 | D9: 0
A10: Monge Vet Solution | B10: 0 | C10: 0 | D10: 0
A11: Monge | B11: 0 | C11: 0 | D11: 0
A13: נוסחה: עלות = מחיר ללא מע"מ × (1 − הנחה) × 1.18 ; מחיר ללקוח = עלות × (1 + מרווח %) + מרווח ₪

Sheet מזון
A1: ספק | B1: פריט | C1: קטגוריה | D1: מק"ט | E1: תאריך מחירון | F1: מחיר ללא מע"מ | G1: מחיר כולל מע"מ | H1: הנחה % | I1: עלות אחרי הנחה (כולל מע"מ) | J1: מרווח % | K1: מרווח ₪ | L1: מחיר ללקוח
A2: Royal Canin VET | B2: ריקברי נוזלי 0.2X3 ליטר | C2: מזון נוזלי, תחליפי חלב לגורים ותוספים | D2: 2491020060 | E2: 2026-06 | F2: 89 | G2: 105.02 | H2: =הגדרות!B2 | I2: =F2*(1-H2/100)*1.18 | J2: =הגדרות!C2 | K2: =הגדרות!D2 | L2: =I2*(1+J2/100)+K2
A3: Royal Canin VET | B3: גסטרואינטסטינל דל שומן נוזל 0.2X3 ליטר | C3: מזון נוזלי, תחליפי חלב לגורים ותוספים | D3: 2491220060 | E3: 2026-06 | F3: 89 | G3: 105.02 | H3: =הגדרות!B2 | I3: =F3*(1-H3/100)*1.18 | J3: =הגדרות!C2 | K3: =הגדרות!D2 | L3: =I3*(1+J3/100)+K3
A4: Royal Canin VET | B4: גסטרואינטסטינל היי אנרגי נוזל 0.2X3 ליטר | C4: מזון נוזלי, תחליפי חלב לגורים ותוספים | D4: 2491320060 | E4: 2026-06 | F4: 89 | G4: 105.02 | H4: =הגדרות!B2 | I4: =F4*(1-H4/100)*1.18 | J4: =הגדרות!C2 | K4: =הגדרות!D2 | L4: =I4*(1+J4/100)+K4
A5: Royal Canin VET | B5: VD רינאל נוזלי חתול 0.2X3 ליטר | C5: מזון נוזלי, תחליפי חלב לגורים ותוספים | D5: 2495120060 | E5: 2026-06 | F5: 89 | G5: 105.02 | H5: =הגדרות!B2 | I5: =F5*(1-H5/100)*1.18 | J5: =הגדרות!C2 | K5: =הגדרות!D2 | L5: =I5*(1+J5/100)+K5
A6: Royal Canin VET | B6: אבקת תחליף חלב לגורי כלב 400 גרם | C6: מזון נוזלי, תחליפי חלב לגורים ותוספים | D6: 2230010040 | E6: 2026-06 | F6: 115 | G6: 135.7 | H6: =הגדרות!B2 | I6: =F6*(1-H6/100)*1.18 | J6: =הגדרות!C2 | K6: =הגדרות!D2 | L6: =I6*(1+J6/100)+K6
A7: Royal Canin VET | B7: ארלי רינאל חתול 3.5 ק"ג | C7: VETERINARY HEALTH NUTRITION CAT - DRY | D7: 2124210350 | E7: 2026-06 | F7: 179 | G7: 211.22 | H7: =הגדרות!B2 | I7: =F7*(1-H7/100)*1.18 | J7: =הגדרות!C2 | K7: =הגדרות!D2 | L7: =I7*(1+J7/100)+K7
A8: Royal Canin VET | B8: רינאל חתול 2 ק"ג | C8: VETERINARY HEALTH NUTRITION CAT - DRY | D8: 2390010200 | E8: 2026-06 | F8: 139 | G8: 164.02 | H8: =הגדרות!B2 | I8: =F8*(1-H8/100)*1.18 | J8: =הגדרות!C2 | K8: =הגדרות!D2 | L8: =I8*(1+J8/100)+K8
A9: Royal Canin VET | B9: רינאל חתול 4 ק"ג | C9: VETERINARY HEALTH NUTRITION CAT - DRY | D9: 2390010400 | E9: 2026-06 | F9: 196 | G9: 231.28 | H9: =הגדרות!B2 | I9: =F9*(1-H9/100)*1.18 | J9: =הגדרות!C2 | K9: =הגדרות!D2 | L9: =I9*(1+J9/100)+K9
A10: Royal Canin VET | B10: רינאל ספיישל חתול 2 ק"ג | C10: VETERINARY HEALTH NUTRITION CAT - DRY | D10: 2394910200 | E10: 2026-06 | F10: 139 | G10: 164.02 | H10: =הגדרות!B2 | I10: =F10*(1-H10/100)*1.18 | J10: =הגדרות!C2 | K10: =הגדרות!D2 | L10: =I10*(1+J10/100)+K10
A11: Royal Canin VET | B11: רינאל ספיישל חתול 4 ק"ג | C11: VETERINARY HEALTH NUTRITION CAT - DRY | D11: 2394910400 | E11: 2026-06 | F11: 196 | G11: 231.28 | H11: =הגדרות!B2 | I11: =F11*(1-H11/100)*1.18 | J11: =הגדרות!C2 | K11: =הגדרות!D2 | L11: =I11*(1+J11/100)+K11
A12: Royal Canin VET | B12: רינאל סלקט חתול 2 ק"ג | C12: VETERINARY HEALTH NUTRITION CAT - DRY | D12: 2416010200 | E12: 2026-06 | F12: 139 | G12: 164.02 | H12: =הגדרות!B2 | I12: =F12*(1-H12/100)*1.18 | J12: =הגדרות!C2 | K12: =הגדרות!D2 | L12: =I12*(1+J12/100)+K12
A13: Royal Canin VET | B13: רינאל סלקט חתול 4 ק"ג | C13: VETERINARY HEALTH NUTRITION CAT - DRY | D13: 2416010400 | E13: 2026-06 | F13: 196 | G13: 231.28 | H13: =הגדרות!B2 | I13: =F13*(1-H13/100)*1.18 | J13: =הגדרות!C2 | K13: =הגדרות!D2 | L13: =I13*(1+J13/100)+K13
A14: Royal Canin VET | B14: מוביליטי חתול 2 ק"ג | C14: VETERINARY HEALTH NUTRITION CAT - DRY | D14: 2394610200 | E14: 2026-06 | F14: 139 | G14: 164.02 | H14: =הגדרות!B2 | I14: =F14*(1-H14/100)*1.18 | J14: =הגדרות!C2 | K14: =הגדרות!D2 | L14: =I14*(1+J14/100)+K14
A15: Royal Canin VET | B15: סטיאטי חתול 3.5 ק"ג | C15: VETERINARY HEALTH NUTRITION CAT - DRY | D15: 2394310350 | E15: 2026-06 | F15: 179 | G15: 211.22 | H15: =הגדרות!B2 | I15: =F15*(1-H15/100)*1.18 | J15: =הגדרות!C2 | K15: =הגדרות!D2 | L15: =I15*(1+J15/100)+K15
A16: Royal Canin VET | B16: סטיאטי חתול 6 ק"ג | C16: VETERINARY HEALTH NUTRITION CAT - DRY | D16: 2394310600 | E16: 2026-06 | F16: 288 | G16: 339.84 | H16: =הגדרות!B2 | I16: =F16*(1-H16/100)*1.18 | J16: =הגדרות!C2 | K16: =הגדרות!D2 | L16: =I16*(1+J16/100)+K16
A17: Royal Canin VET | B17: דיאבטיק חתול 3.5 ק"ג | C17: VETERINARY HEALTH NUTRITION CAT - DRY | D17: 2390610350 | E17: 2026-06 | F17: 179 | G17: 211.22 | H17: =הגדרות!B2 | I17: =F17*(1-H17/100)*1.18 | J17: =הגדרות!C2 | K17: =הגדרות!D2 | L17: =I17*(1+J17/100)+K17
A18: Royal Canin VET | B18: ניוטרד סטאיטי באלאנס חתול 3.5 ק"ג | C18: VETERINARY HEALTH NUTRITION CAT - DRY | D18: 2272110350 | E18: 2026-06 | F18: 159 | G18: 187.62 | H18: =הגדרות!B2 | I18: =F18*(1-H18/100)*1.18 | J18: =הגדרות!C2 | K18: =הגדרות!D2 | L18: =I18*(1+J18/100)+K18
A19: Royal Canin VET | B19: גסטרואינטסטינל קיטן חתול 2 ק"ג | C19: VETERINARY HEALTH NUTRITION CAT - DRY | D19: 2122810200 | E19: 2026-06 | F19: 143 | G19: 168.74 | H19: =הגדרות!B2 | I19: =F19*(1-H19/100)*1.18 | J19: =הגדרות!C2 | K19: =הגדרות!D2 | L19: =I19*(1+J19/100)+K19
A20: Royal Canin VET | B20: גסטרואינטסטינל חתול 2 ק"ג | C20: VETERINARY HEALTH NUTRITION CAT - DRY | D20: 2390510200 | E20: 2026-06 | F20: 139 | G20: 164.02 | H20: =הגדרות!B2 | I20: =F20*(1-H20/100)*1.18 | J20: =הגדרות!C2 | K20: =הגדרות!D2 | L20: =I20*(1+J20/100)+K20
A21: Royal Canin VET | B21: גסטרואינטסטינל חתול 4 ק"ג | C21: VETERINARY HEALTH NUTRITION CAT - DRY | D21: 2390510400 | E21: 2026-06 | F21: 215 | G21: 253.7 | H21: =הגדרות!B2 | I21: =F21*(1-H21/100)*1.18 | J21: =הגדרות!C2 | K21: =הגדרות!D2 | L21: =I21*(1+J21/100)+K21
A22: Royal Canin VET | B22: גסטרואינטסטינל מופחת קלוריות חתול 2 ק"ג | C22: VETERINARY HEALTH NUTRITION CAT - DRY | D22: 2400810200 | E22: 2026-06 | F22: 139 | G22: 164.02 | H22: =הגדרות!B2 | I22: =F22*(1-H22/100)*1.18 | J22: =הגדרות!C2 | K22: =הגדרות!D2 | L22: =I22*(1+J22/100)+K22
A23: Royal Canin VET | B23: גסטרואינטסטינל היירבול 4 ק"ג | C23: VETERINARY HEALTH NUTRITION CAT - DRY | D23: 2272210400 | E23: 2026-06 | F23: 223 | G23: 263.14 | H23: =הגדרות!B2 | I23: =F23*(1-H23/100)*1.18 | J23: =הגדרות!C2 | K23: =הגדרות!D2 | L23: =I23*(1+J23/100)+K23
A24: Royal Canin VET | B24: גסטרואינטסטינל פייבר ריספונס חתול 2 ק"ג | C24: VETERINARY HEALTH NUTRITION CAT - DRY | D24: 2400710200 | E24: 2026-06 | F24: 139 | G24: 164.02 | H24: =הגדרות!B2 | I24: =F24*(1-H24/100)*1.18 | J24: =הגדרות!C2 | K24: =הגדרות!D2 | L24: =I24*(1+J24/100)+K24
A25: Royal Canin VET | B25: סנסטיביטי קונטרול חתול 3.5 ק"ג | C25: VETERINARY HEALTH NUTRITION CAT - DRY | D25: 2390910350 | E25: 2026-06 | F25: 179 | G25: 211.22 | H25: =הגדרות!B2 | I25: =F25*(1-H25/100)*1.18 | J25: =הגדרות!C2 | K25: =הגדרות!D2 | L25: =I25*(1+J25/100)+K25
A26: Royal Canin VET | B26: אנאלרג'ניק חתול 2 ק"ג | C26: VETERINARY HEALTH NUTRITION CAT - DRY | D26: 2195010200 | E26: 2026-06 | F26: 145 | G26: 171.1 | H26: =הגדרות!B2 | I26: =F26*(1-H26/100)*1.18 | J26: =הגדרות!C2 | K26: =הגדרות!D2 | L26: =I26*(1+J26/100)+K26
A27: Royal Canin VET | B27: היפואלרגני חתול 2.5 ק"ג | C27: VETERINARY HEALTH NUTRITION CAT - DRY | D27: 2390210250 | E27: 2026-06 | F27: 153 | G27: 180.54 | H27: =הגדרות!B2 | I27: =F27*(1-H27/100)*1.18 | J27: =הגדרות!C2 | K27: =הגדרות!D2 | L27: =I27*(1+J27/100)+K27
A28: Royal Canin VET | B28: היפואלרגני חתול 4.5 ק"ג | C28: VETERINARY HEALTH NUTRITION CAT - DRY | D28: 2390210450 | E28: 2026-06 | F28: 264 | G28: 311.52 | H28: =הגדרות!B2 | I28: =F28*(1-H28/100)*1.18 | J28: =הגדרות!C2 | K28: =הגדרות!D2 | L28: =I28*(1+J28/100)+K28
A29: Royal Canin VET | B29: סקין&קואט חתול 3.5 ק"ג | C29: VETERINARY HEALTH NUTRITION CAT - DRY | D29: 2132310350 | E29: 2026-06 | F29: 159 | G29: 187.62 | H29: =הגדרות!B2 | I29: =F29*(1-H29/100)*1.18 | J29: =הגדרות!C2 | K29: =הגדרות!D2 | L29: =I29*(1+J29/100)+K29
A30: Royal Canin VET | B30: הפטיק חתול 4 ק"ג | C30: VETERINARY HEALTH NUTRITION CAT - DRY | D30: 2401210400 | E30: 2026-06 | F30: 215 | G30: 253.7 | H30: =הגדרות!B2 | I30: =F30*(1-H30/100)*1.18 | J30: =הגדרות!C2 | K30: =הגדרות!D2 | L30: =I30*(1+J30/100)+K30
A31: Royal Canin VET | B31: יורינרי S/O חתול 1.5 ק"ג | C31: VETERINARY HEALTH NUTRITION CAT - DRY | D31: 2390110150 | E31: 2026-06 | F31: 109 | G31: 128.62 | H31: =הגדרות!B2 | I31: =F31*(1-H31/100)*1.18 | J31: =הגדרות!C2 | K31: =הגדרות!D2 | L31: =I31*(1+J31/100)+K31
A32: Royal Canin VET | B32: יורינרי S/O חתול 3.5 ק"ג | C32: VETERINARY HEALTH NUTRITION CAT - DRY | D32: 2390110350 | E32: 2026-06 | F32: 179 | G32: 211.22 | H32: =הגדרות!B2 | I32: =F32*(1-H32/100)*1.18 | J32: =הגדרות!C2 | K32: =הגדרות!D2 | L32: =I32*(1+J32/100)+K32
A33: Royal Canin VET | B33: יורינרי S/O חתול 7 ק"ג | C33: VETERINARY HEALTH NUTRITION CAT - DRY | D33: 2390110700 | E33: 2026-06 | F33: 299 | G33: 352.82 | H33: =הגדרות!B2 | I33: =F33*(1-H33/100)*1.18 | J33: =הגדרות!C2 | K33: =הגדרות!D2 | L33: =I33*(1+J33/100)+K33
A34: Royal Canin VET | B34: יורינרי S/O חתול 9 ק"ג | C34: VETERINARY HEALTH NUTRITION CAT - DRY | D34: 2390110900 | E34: 2026-06 | F34: 352 | G34: 415.36 | H34: =הגדרות!B2 | I34: =F34*(1-H34/100)*1.18 | J34: =הגדרות!C2 | K34: =הגדרות!D2 | L34: =I34*(1+J34/100)+K34
A35: Royal Canin VET | B35: יורינרי מופ' קל' חתול 3.5 ק"ג | C35: VETERINARY HEALTH NUTRITION CAT - DRY | D35: 2395410350 | E35: 2026-06 | F35: 179 | G35: 211.22 | H35: =הגדרות!B2 | I35: =F35*(1-H35/100)*1.18 | J35: =הגדרות!C2 | K35: =הגדרות!D2 | L35: =I35*(1+J35/100)+K35
A36: Royal Canin VET | B36: ריקברי חתול / כלב 195X12 גרם שימורים | C36: VETERINARY HEALTH NUTRITION CAT - WET | D36: 2405520019 | E36: 2026-06 | F36: 179 | G36: 211.22 | H36: =הגדרות!B2 | I36: =F36*(1-H36/100)*1.18 | J36: =הגדרות!C2 | K36: =הגדרות!D2 | L36: =I36*(1+J36/100)+K36
A37: Royal Canin VET | B37: גסטרואינטסטינל קיטן מוס רך במיוחד 195X12 גרם שימורים | C37: VETERINARY HEALTH NUTRITION CAT - WET | D37: 2122720019 | E37: 2026-06 | F37: 139 | G37: 164.02 | H37: =הגדרות!B2 | I37: =F37*(1-H37/100)*1.18 | J37: =הגדרות!C2 | K37: =הגדרות!D2 | L37: =I37*(1+J37/100)+K37
A38: Royal Canin VET | B38: גסטרואינטסטינל מופחת קלוריות לחתול 85X12 גרם פאוץ' | C38: VETERINARY HEALTH NUTRITION CAT - WET | D38: 2400920102 | E38: 2026-06 | F38: 89 | G38: 105.02 | H38: =הגדרות!B2 | I38: =F38*(1-H38/100)*1.18 | J38: =הגדרות!C2 | K38: =הגדרות!D2 | L38: =I38*(1+J38/100)+K38
A39: Royal Canin VET | B39: גסטרואינטסטינל לחתול 85X12 גרם פאוץ' | C39: VETERINARY HEALTH NUTRITION CAT - WET | D39: 2403920102 | E39: 2026-06 | F39: 89 | G39: 105.02 | H39: =הגדרות!B2 | I39: =F39*(1-H39/100)*1.18 | J39: =הגדרות!C2 | K39: =הגדרות!D2 | L39: =I39*(1+J39/100)+K39
A40: Royal Canin VET | B40: גסטרואינטסטינל פייבר רספונס 85X12 גרם פאוץ' | C40: VETERINARY HEALTH NUTRITION CAT - WET | D40: 2273320102 | E40: 2026-06 | F40: 89 | G40: 105.02 | H40: =הגדרות!B2 | I40: =F40*(1-H40/100)*1.18 | J40: =הגדרות!C2 | K40: =הגדרות!D2 | L40: =I40*(1+J40/100)+K40
...
