Workbook

Sheet הגדרות
A1: ספק | B1: ההנחה שלי % | C1: מרווח % | D1: מרווח ₪ קבוע
A2: בית ארז (מילטין) | B2: 0 | C2: 0 | D2: 0
A3: MSD (ברווקטו) | B3: 0 | C3: 0 | D3: 0
A4: בית ארז — ציוד מתכלה | B4: 0 | C4: 0 | D4: 0
A5: זואטיס (Zoetis) | B5: 0 | C5: 0 | D5: 0
A6: וטמרקט | B6: 0 | C6: 0 | D6: 0
A7: מדי-מרקט | B7: 0 | C7: 0 | D7: 0
A8: פט-וט ביומד | B8: 0 | C8: 0 | D8: 0
A10: נוסחה: עלות = מחיר ללא מע"מ × (1 − הנחה) × 1.18 ; מחיר ללקוח = עלות × (1 + מרווח %) + מרווח ₪

Sheet מוצרים ותרופות
A1: ספק | B1: פריט | C1: קטגוריה | D1: מק"ט | E1: תאריך מחירון | F1: מחיר ללא מע"מ | G1: מחיר כולל מע"מ | H1: הנחה % | I1: עלות אחרי הנחה (כולל מע"מ) | J1: מרווח % | K1: מרווח ₪ | L1: מחיר ללקוח
A2: בית ארז (מילטין) | B2: נקסגארד קומבו לחתול עד 2.5 ק"ג (S) | C2: הדברה | E2: 2026-07 | F2: 183 | G2: 215.94 | H2: =הגדרות!B2 | I2: =F2*(1-H2/100)*1.18 | J2: =הגדרות!C2 | K2: =הגדרות!D2 | L2: =I2*(1+J2/100)+K2
A3: בית ארז (מילטין) | B3: נקסגארד קומבו לחתול 2.5-7.5 ק"ג (L) | C3: הדברה | E3: 2026-07 | F3: 195 | G3: 230.1 | H3: =הגדרות!B2 | I3: =F3*(1-H3/100)*1.18 | J3: =הגדרות!C2 | K3: =הגדרות!D2 | L3: =I3*(1+J3/100)+K3
A4: בית ארז (מילטין) | B4: נקסגארד 2-4 ק"ג (S) | C4: הדברה | E4: 2026-07 | F4: 155 | G4: 182.9 | H4: =הגדרות!B2 | I4: =F4*(1-H4/100)*1.18 | J4: =הגדרות!C2 | K4: =הגדרות!D2 | L4: =I4*(1+J4/100)+K4
A5: בית ארז (מילטין) | B5: נקסגארד 4-10 ק"ג (M) | C5: הדברה | E5: 2026-07 | F5: 178 | G5: 210.04 | H5: =הגדרות!B2 | I5: =F5*(1-H5/100)*1.18 | J5: =הגדרות!C2 | K5: =הגדרות!D2 | L5: =I5*(1+J5/100)+K5
A6: בית ארז (מילטין) | B6: נקסגארד 10-25 ק"ג (L) | C6: הדברה | E6: 2026-07 | F6: 185 | G6: 218.3 | H6: =הגדרות!B2 | I6: =F6*(1-H6/100)*1.18 | J6: =הגדרות!C2 | K6: =הגדרות!D2 | L6: =I6*(1+J6/100)+K6
A7: בית ארז (מילטין) | B7: נקסגארד 25-50 ק"ג (XL) | C7: הדברה | E7: 2026-07 | F7: 214 | G7: 252.52 | H7: =הגדרות!B2 | I7: =F7*(1-H7/100)*1.18 | J7: =הגדרות!C2 | K7: =הגדרות!D2 | L7: =I7*(1+J7/100)+K7
A8: בית ארז (מילטין) | B8: נקסגארד ספקטרה 2-3.5 ק"ג (XS) | C8: הדברה | E8: 2026-07 | F8: 174 | G8: 205.32 | H8: =הגדרות!B2 | I8: =F8*(1-H8/100)*1.18 | J8: =הגדרות!C2 | K8: =הגדרות!D2 | L8: =I8*(1+J8/100)+K8
A9: בית ארז (מילטין) | B9: נקסגארד ספקטרה 3.5-7.5 ק"ג (S) | C9: הדברה | E9: 2026-07 | F9: 186 | G9: 219.48 | H9: =הגדרות!B2 | I9: =F9*(1-H9/100)*1.18 | J9: =הגדרות!C2 | K9: =הגדרות!D2 | L9: =I9*(1+J9/100)+K9
A10: בית ארז (מילטין) | B10: נקסגארד ספקטרה 7.5-15 ק"ג (M) | C10: הדברה | E10: 2026-07 | F10: 225 | G10: 265.5 | H10: =הגדרות!B2 | I10: =F10*(1-H10/100)*1.18 | J10: =הגדרות!C2 | K10: =הגדרות!D2 | L10: =I10*(1+J10/100)+K10
A11: בית ארז (מילטין) | B11: נקסגארד ספקטרה 15-30 ק"ג (L) | C11: הדברה | E11: 2026-07 | F11: 248 | G11: 292.64 | H11: =הגדרות!B2 | I11: =F11*(1-H11/100)*1.18 | J11: =הגדרות!C2 | K11: =הגדרות!D2 | L11: =I11*(1+J11/100)+K11
A12: בית ארז (מילטין) | B12: נקסגארד ספקטרה 30-60 ק"ג (XL) | C12: הדברה | E12: 2026-07 | F12: 271 | G12: 319.78 | H12: =הגדרות!B2 | I12: =F12*(1-H12/100)*1.18 | J12: =הגדרות!C2 | K12: =הגדרות!D2 | L12: =I12*(1+J12/100)+K12
A13: בית ארז (מילטין) | B13: תרכיב Purevax RCP פיורווקס משולש 10 - יח' של מנה | C13: חיסונים | E13: 2026-07 | F13: 320 | G13: 377.6 | H13: =הגדרות!B2 | I13: =F13*(1-H13/100)*1.18 | J13: =הגדרות!C2 | K13: =הגדרות!D2 | L13: =I13*(1+J13/100)+K13
A14: בית ארז (מילטין) | B14: תרכיב Purevax RCPCH פיורוקס מרובע 10 - יח' של מנה | C14: חיסונים | E14: 2026-07 | F14: 400 | G14: 472 | H14: =הגדרות!B2 | I14: =F14*(1-H14/100)*1.18 | J14: =הגדרות!C2 | K14: =הגדרות!D2 | L14: =I14*(1+J14/100)+K14
A15: בית ארז (מילטין) | B15: תרכיב Purevax Rabies פיורוקס כלבת 10 - יח' של מנה | C15: חיסונים | E15: 2026-07 | F15: 300 | G15: 354 | H15: =הגדרות!B2 | I15: =F15*(1-H15/100)*1.18 | J15: =הגדרות!C2 | K15: =הגדרות!D2 | L15: =I15*(1+J15/100)+K15
A16: בית ארז (מילטין) | B16: תרכיב Primodog פרימודוג 10 - יח' של מנה | C16: חיסונים | E16: 2026-07 | F16: 310 | G16: 365.8 | H16: =הגדרות!B2 | I16: =F16*(1-H16/100)*1.18 | J16: =הגדרות!C2 | K16: =הגדרות!D2 | L16: =I16*(1+J16/100)+K16
A17: בית ארז (מילטין) | B17: תרכיב Recombitek C8 רקומביטק 25 - יח' של מנה | C17: חיסונים | E17: 2026-07 | F17: 600 | G17: 708 | H17: =הגדרות!B2 | I17: =F17*(1-H17/100)*1.18 | J17: =הגדרות!C2 | K17: =הגדרות!D2 | L17: =I17*(1+J17/100)+K17
A18: בית ארז (מילטין) | B18: קאניוורם פסטה תילוע 10 מ"ל Caniverm - | C18: תילוע | E18: 2026-07 | F18: 79 | G18: 93.22 | H18: =הגדרות!B2 | I18: =F18*(1-H18/100)*1.18 | J18: =הגדרות!C2 | K18: =הגדרות!D2 | L18: =I18*(1+J18/100)+K18
A19: בית ארז (מילטין) | B19: דולפאק 60) 10 טבליות) | C19: תילוע | E19: 2026-07 | F19: 240 | G19: 283.2 | H19: =הגדרות!B2 | I19: =F19*(1-H19/100)*1.18 | J19: =הגדרות!C2 | K19: =הגדרות!D2 | L19: =I19*(1+J19/100)+K19
A20: בית ארז (מילטין) | B20: דולפאק 60) 25 טבליות) | C20: תילוע | E20: 2026-07 | F20: 570 | G20: 672.6 | H20: =הגדרות!B2 | I20: =F20*(1-H20/100)*1.18 | J20: =הגדרות!C2 | K20: =הגדרות!D2 | L20: =I20*(1+J20/100)+K20
A21: בית ארז (מילטין) | B21: קלמיווט להזרקה 50 - מ"ל | C21: הרדמה | E21: 2026-07 | F21: 50 | G21: 59 | H21: =הגדרות!B2 | I21: =F21*(1-H21/100)*1.18 | J21: =הגדרות!C2 | K21: =הגדרות!D2 | L21: =I21*(1+J21/100)+K21
A22: בית ארז (מילטין) | B22: מורפסול (בוטרפנול 20 - (1% מ"ל | C22: הרדמה | E22: 2026-07 | F22: 335 | G22: 395.3 | H22: =הגדרות!B2 | I22: =F22*(1-H22/100)*1.18 | J22: =הגדרות!C2 | K22: =הגדרות!D2 | L22: =I22*(1+J22/100)+K22
A23: בית ארז (מילטין) | B23: סדקסילאן (קסילזין 25 (2% מ"ל | C23: הרדמה | E23: 2026-07 | F23: 140 | G23: 165.2 | H23: =הגדרות!B2 | I23: =F23*(1-H23/100)*1.18 | J23: =הגדרות!C2 | K23: =הגדרות!D2 | L23: =I23*(1+J23/100)+K23
A24: בית ארז (מילטין) | B24: פרופופול ליפורו 20 - 1% מ"ל 5 - אמפולות | C24: הרדמה | E24: 2026-07 | F24: 45 | G24: 53.1 | H24: =הגדרות!B2 | I24: =F24*(1-H24/100)*1.18 | J24: =הגדרות!C2 | K24: =הגדרות!D2 | L24: =I24*(1+J24/100)+K24
A25: בית ארז (מילטין) | B25: פרופופול ליפורו 50 - 2% מ"ל | C25: הרדמה | E25: 2026-07 | F25: 32 | G25: 37.76 | H25: =הגדרות!B2 | I25: =F25*(1-H25/100)*1.18 | J25: =הגדרות!C2 | K25: =הגדרות!D2 | L25: =I25*(1+J25/100)+K25
A26: בית ארז (מילטין) | B26: Lidocaine לידוקאין 10 - 1% מ"ל 20 - יח' | C26: הרדמה | E26: 2026-07 | F26: 40 | G26: 47.2 | H26: =הגדרות!B2 | I26: =F26*(1-H26/100)*1.18 | J26: =הגדרות!C2 | K26: =הגדרות!D2 | L26: =I26*(1+J26/100)+K26
A27: בית ארז (מילטין) | B27: Lidocaine לידוקאין 10 - 2% מ"ל 20 - יח' | C27: הרדמה | E27: 2026-07 | F27: 50 | G27: 59 | H27: =הגדרות!B2 | I27: =F27*(1-H27/100)*1.18 | J27: =הגדרות!C2 | K27: =הגדרות!D2 | L27: =I27*(1+J27/100)+K27
A28: בית ארז (מילטין) | B28: קלמג'ין 50% להזרקה 100 - מ"ל | C28: NSAID | E28: 2026-07 | F28: 84 | G28: 99.12 | H28: =הגדרות!B2 | I28: =F28*(1-H28/100)*1.18 | J28: =הגדרות!C2 | K28: =הגדרות!D2 | L28: =I28*(1+J28/100)+K28
A29: בית ארז (מילטין) | B29: לוקסיקום (מלוקסיקם) 0.5 מג/מל 15 - מ"ל | C29: NSAID | E29: 2026-07 | F29: 50 | G29: 59 | H29: =הגדרות!B2 | I29: =F29*(1-H29/100)*1.18 | J29: =הגדרות!C2 | K29: =הגדרות!D2 | L29: =I29*(1+J29/100)+K29
A30: בית ארז (מילטין) | B30: לוקסיקום S.A להזרקה (מלוקסיקם 5 מג/מל) 20 - מ"ל | C30: NSAID | E30: 2026-07 | F30: 145 | G30: 171.1 | H30: =הגדרות!B2 | I30: =F30*(1-H30/100)*1.18 | J30: =הגדרות!C2 | K30: =הגדרות!D2 | L30: =I30*(1+J30/100)+K30
A31: בית ארז (מילטין) | B31: פרוויקוקס 57 מ"ג 60) טבליות) | C31: NSAID | E31: 2026-07 | F31: 225 | G31: 265.5 | H31: =הגדרות!B2 | I31: =F31*(1-H31/100)*1.18 | J31: =הגדרות!C2 | K31: =הגדרות!D2 | L31: =I31*(1+J31/100)+K31
A32: בית ארז (מילטין) | B32: פרוויקוקס 227 מ"ג 60) טבליות) | C32: NSAID | E32: 2026-07 | F32: 465 | G32: 548.7 | H32: =הגדרות!B2 | I32: =F32*(1-H32/100)*1.18 | J32: =הגדרות!C2 | K32: =הגדרות!D2 | L32: =I32*(1+J32/100)+K32
A33: בית ארז (מילטין) | B33: הרפלס פלוס אבקה 30 - ג' | C33: עיניים | E33: 2026-07 | F33: 47 | G33: 55.46 | H33: =הגדרות!B2 | I33: =F33*(1-H33/100)*1.18 | J33: =הגדרות!C2 | K33: =הגדרות!D2 | L33: =I33*(1+J33/100)+K33
A34: בית ארז (מילטין) | B34: אופטיווט - נוזל ניקוי הפרווה באזור העין 50 מ"ל | C34: עיניים | E34: 2026-07 | F34: 18 | G34: 21.24 | H34: =הגדרות!B2 | I34: =F34*(1-H34/100)*1.18 | J34: =הגדרות!C2 | K34: =הגדרות!D2 | L34: =I34*(1+J34/100)+K34
A35: בית ארז (מילטין) | B35: סנוצין פורטה תמיסה לניקוי עיניים 50 מ"ל | C35: עיניים | E35: 2026-07 | F35: 44 | G35: 51.92 | H35: =הגדרות!B2 | I35: =F35*(1-H35/100)*1.18 | J35: =הגדרות!C2 | K35: =הגדרות!D2 | L35: =I35*(1+J35/100)+K35
A36: בית ארז (מילטין) | B36: פלאק איז 75 - ג' (PlaqEase) | C36: דנטלי | E36: 2026-07 | F36: 82 | G36: 96.76 | H36: =הגדרות!B2 | I36: =F36*(1-H36/100)*1.18 | J36: =הגדרות!C2 | K36: =הגדרות!D2 | L36: =I36*(1+J36/100)+K36
A37: בית ארז (מילטין) | B37: פלאק איז 150 - ג' (PlaqEase) | C37: דנטלי | E37: 2026-07 | F37: 140 | G37: 165.2 | H37: =הגדרות!B2 | I37: =F37*(1-H37/100)*1.18 | J37: =הגדרות!C2 | K37: =הגדרות!D2 | L37: =I37*(1+J37/100)+K37
A38: בית ארז (מילטין) | B38: דנטיהקס 20 - ג' | C38: דנטלי | E38: 2026-07 | F38: 48 | G38: 56.64 | H38: =הגדרות!B2 | I38: =F38*(1-H38/100)*1.18 | J38: =הגדרות!C2 | K38: =הגדרות!D2 | L38: =I38*(1+J38/100)+K38
A39: בית ארז (מילטין) | B39: אקטאה אורל 15 - מ"ל | C39: דנטלי | E39: 2026-07 | F39: 56 | G39: 66.08 | H39: =הגדרות!B2 | I39: =F39*(1-H39/100)*1.18 | J39: =הגדרות!C2 | K39: =הגדרות!D2 | L39: =I39*(1+J39/100)+K39
A40: בית ארז (מילטין) | B40: דנטלפט - ספריי דנטלי לכלב וחתול 125 מ"ל | C40: דנטלי | E40: 2026-07 | F40: 21 | G40: 24.78 | H40: =הגדרות!B2 | I40: =F40*(1-H40/100)*1.18 | J40: =הגדרות!C2 | K40: =הגדרות!D2 | L40: =I40*(1+J40/100)+K40
...
