Workbook

Sheet הגדרות
A1: ספק | B1: ההנחה שלי % | C1: מרווח % | D1: מרווח ₪ קבוע
A2: בית ארז (מילטין) | B2: 0 | C2: 0 | D2: 0
A3: קונג (Kong) | B3: 0 | C3: 0 | D3: 0
A4: פרפלסט (Ferplast) | B4: 0 | C4: 0 | D4: 0
A5: וטמרקט | B5: 0 | C5: 0 | D5: 0
A6: מדי-מרקט | B6: 0 | C6: 0 | D6: 0
A7: פט-וט ביומד | B7: 0 | C7: 0 | D7: 0
A8: פורינה (חנויות) | B8: 0 | C8: 0 | D8: 0
A10: נוסחה: עלות = מחיר ללא מע"מ × (1 − הנחה) × 1.18 ; מחיר ללקוח = עלות × (1 + מרווח %) + מרווח ₪

Sheet מוצרי חנויות
A1: ספק | B1: פריט | C1: קטגוריה | D1: מק"ט | E1: תאריך מחירון | F1: מחיר ללא מע"מ | G1: מחיר כולל מע"מ | H1: הנחה % | I1: עלות אחרי הנחה (כולל מע"מ) | J1: מרווח % | K1: מרווח ₪ | L1: מחיר ללקוח
A2: בית ארז (מילטין) | B2: טריקי טריטס עוף 2X15 - חטיפים לכלב וחתול Tricky Treats | C2: חטיפים | E2: 2026-07 | F2: 44 | G2: 51.92 | H2: =הגדרות!B2 | I2: =F2*(1-H2/100)*1.18 | J2: =הגדרות!C2 | K2: =הגדרות!D2 | L2: =I2*(1+J2/100)+K2
A3: בית ארז (מילטין) | B3: טריקי טריטס עוף 2X200 - חטיפים לכלב וחתול Tricky Treats | C3: חטיפים | E3: 2026-07 | F3: 300 | G3: 354 | H3: =הגדרות!B2 | I3: =F3*(1-H3/100)*1.18 | J3: =הגדרות!C2 | K3: =הגדרות!D2 | L3: =I3*(1+J3/100)+K3
A4: בית ארז (מילטין) | B4: טריקי טריטס ברווז 2X15 - חטיפים לכלב וחתול Tricky Treats | C4: חטיפים | E4: 2026-07 | F4: 44 | G4: 51.92 | H4: =הגדרות!B2 | I4: =F4*(1-H4/100)*1.18 | J4: =הגדרות!C2 | K4: =הגדרות!D2 | L4: =I4*(1+J4/100)+K4
A5: בית ארז (מילטין) | B5: טריקי טריטס ברווז 2X200 - חטיפים לכלב וחתול Tricky Treats | C5: חטיפים | E5: 2026-07 | F5: 300 | G5: 354 | H5: =הגדרות!B2 | I5: =F5*(1-H5/100)*1.18 | J5: =הגדרות!C2 | K5: =הגדרות!D2 | L5: =I5*(1+J5/100)+K5
A6: בית ארז (מילטין) | B6: מקלון למד סוכר 50 יח' Accu-Chek Instant Roche | C6: חטיפים | E6: 2026-07 | F6: 75 | G6: 88.5 | H6: =הגדרות!B2 | I6: =F6*(1-H6/100)*1.18 | J6: =הגדרות!C2 | K6: =הגדרות!D2 | L6: =I6*(1+J6/100)+K6
A7: קונג (Kong) | B7: קונג סקראטלס פנדה 2 במארז (CA122) | C7: צעצועים | D7: 376000590 | E7: 2026-08 | F7: 31 | G7: 36.58 | H7: =הגדרות!B3 | I7: =F7*(1-H7/100)*1.18 | J7: =הגדרות!C3 | K7: =הגדרות!D3 | L7: =I7*(1+J7/100)+K7
A8: קונג (Kong) | B8: קונג סקראטלס עוף 2 במארז (CA123) | C8: צעצועים | D8: 376000591 | E8: 2026-08 | F8: 31 | G8: 36.58 | H8: =הגדרות!B3 | I8: =F8*(1-H8/100)*1.18 | J8: =הגדרות!C3 | K8: =הגדרות!D3 | L8: =I8*(1+J8/100)+K8
A9: קונג (Kong) | B9: קונג גחלילית זוהרת (CT65) | C9: צעצועים | D9: 376000592 | E9: 2026-08 | F9: 53 | G9: 62.54 | H9: =הגדרות!B3 | I9: =F9*(1-H9/100)*1.18 | J9: =הגדרות!C3 | K9: =הגדרות!D3 | L9: =I9*(1+J9/100)+K9
A10: קונג (Kong) | B10: קונג כדורגל ספורטיבי גמיש מדיום (FLBS2) | C10: צעצועים | D10: 376000593 | E10: 2026-08 | F10: 56 | G10: 66.08 | H10: =הגדרות!B3 | I10: =F10*(1-H10/100)*1.18 | J10: =הגדרות!C3 | K10: =הגדרות!D3 | L10: =I10*(1+J10/100)+K10
A11: קונג (Kong) | B11: קונג כדורגל ספורטיבי גמיש לארג (FLBSX) | C11: צעצועים | D11: 376000594 | E11: 2026-08 | F11: 93 | G11: 109.74 | H11: =הגדרות!B3 | I11: =F11*(1-H11/100)*1.18 | J11: =הגדרות!C3 | K11: =הגדרות!D3 | L11: =I11*(1+J11/100)+K11
A12: קונג (Kong) | B12: קונג בובת קשרים תרנגולת (NKC1) | C12: צעצועים | D12: 376000595 | E12: 2026-08 | F12: 56 | G12: 66.08 | H12: =הגדרות!B3 | I12: =F12*(1-H12/100)*1.18 | J12: =הגדרות!C3 | K12: =הגדרות!D3 | L12: =I12*(1+J12/100)+K12
A13: קונג (Kong) | B13: קונג בובת קשרים תרנגולת קטנה (NKC3) | C13: צעצועים | D13: 376000596 | E13: 2026-08 | F13: 38 | G13: 44.84 | H13: =הגדרות!B3 | I13: =F13*(1-H13/100)*1.18 | J13: =הגדרות!C3 | K13: =הגדרות!D3 | L13: =I13*(1+J13/100)+K13
A14: קונג (Kong) | B14: קונג בובת קשרים תרנגולת אקסטרה (NKCX) | C14: צעצועים | D14: 376000597 | E14: 2026-08 | F14: 83 | G14: 97.94 | H14: =הגדרות!B3 | I14: =F14*(1-H14/100)*1.18 | J14: =הגדרות!C3 | K14: =הגדרות!D3 | L14: =I14*(1+J14/100)+K14
A15: קונג (Kong) | B15: קונג לקקן לכלבים אקסטרה (PLPX) | C15: צעצועים | D15: 376000598 | E15: 2026-08 | F15: 49 | G15: 57.82 | H15: =הגדרות!B3 | I15: =F15*(1-H15/100)*1.18 | J15: =הגדרות!C3 | K15: =הגדרות!D3 | L15: =I15*(1+J15/100)+K15
A16: קונג (Kong) | B16: קונג משחק עכבר לחתול (CA118) | C16: צעצועים | D16: 376000599 | E16: 2026-08 | F16: 21 | G16: 24.78 | H16: =הגדרות!B3 | I16: =F16*(1-H16/100)*1.18 | J16: =הגדרות!C3 | K16: =הגדרות!D3 | L16: =I16*(1+J16/100)+K16
A17: קונג (Kong) | B17: קונג ביצת קאטניפ 2 במארז (CA121) | C17: צעצועים | D17: 376000600 | E17: 2026-08 | F17: 30 | G17: 35.4 | H17: =הגדרות!B3 | I17: =F17*(1-H17/100)*1.18 | J17: =הגדרות!C3 | K17: =הגדרות!D3 | L17: =I17*(1+J17/100)+K17
A18: קונג (Kong) | B18: קונג משחק דרקון לחתול (CA92) | C18: צעצועים | D18: 376000601 | E18: 2026-08 | F18: 26 | G18: 30.68 | H18: =הגדרות!B3 | I18: =F18*(1-H18/100)*1.18 | J18: =הגדרות!C3 | K18: =הגדרות!D3 | L18: =I18*(1+J18/100)+K18
A19: קונג (Kong) | B19: קונג בובת נוייזי הבונה (NQ3) | C19: צעצועים | D19: 376000603 | E19: 2026-08 | F19: 21 | G19: 24.78 | H19: =הגדרות!B3 | I19: =F19*(1-H19/100)*1.18 | J19: =הגדרות!C3 | K19: =הגדרות!D3 | L19: =I19*(1+J19/100)+K19
A20: קונג (Kong) | B20: קונג בובת נוייזי הברווז (NY5) | C20: צעצועים | D20: 376000604 | E20: 2026-08 | F20: 15 | G20: 17.7 | H20: =הגדרות!B3 | I20: =F20*(1-H20/100)*1.18 | J20: =הגדרות!C3 | K20: =הגדרות!D3 | L20: =I20*(1+J20/100)+K20
A21: קונג (Kong) | B21: קונג בובת צפרדע מיני (SNZM51) | C21: צעצועים | D21: 376000605 | E21: 2026-08 | F21: 26 | G21: 30.68 | H21: =הגדרות!B3 | I21: =F21*(1-H21/100)*1.18 | J21: =הגדרות!C3 | K21: =הגדרות!D3 | L21: =I21*(1+J21/100)+K21
A22: קונג (Kong) | B22: קונג בובת מיני חזיר (SNZM52) | C22: צעצועים | D22: 376000606 | E22: 2026-08 | F22: 26 | G22: 30.68 | H22: =הגדרות!B3 | I22: =F22*(1-H22/100)*1.18 | J22: =הגדרות!C3 | K22: =הגדרות!D3 | L22: =I22*(1+J22/100)+K22
A23: קונג (Kong) | B23: קונג מקל משחק בטיחותי בינוני (PF2) | C23: צעצועים | D23: 376000017 | E23: 2026-08 | F23: 57 | G23: 67.26 | H23: =הגדרות!B3 | I23: =F23*(1-H23/100)*1.18 | J23: =הגדרות!C3 | K23: =הגדרות!D3 | L23: =I23*(1+J23/100)+K23
A24: קונג (Kong) | B24: קונג מקל משחק בטיחותי קטן (PF3) | C24: צעצועים | D24: 376000018 | E24: 2026-08 | F24: 38 | G24: 44.84 | H24: =הגדרות!B3 | I24: =F24*(1-H24/100)*1.18 | J24: =הגדרות!C3 | K24: =הגדרות!D3 | L24: =I24*(1+J24/100)+K24
A25: קונג (Kong) | B25: קונג כדור KB1) M) | C25: צעצועים | D25: 376000026 | E25: 2026-08 | F25: 55 | G25: 64.9 | H25: =הגדרות!B3 | I25: =F25*(1-H25/100)*1.18 | J25: =הגדרות!C3 | K25: =הגדרות!D3 | L25: =I25*(1+J25/100)+K25
A26: קונג (Kong) | B26: קונג S לגורים KP3 | C26: צעצועים | D26: 376000029 | E26: 2026-08 | F26: 33 | G26: 38.94 | H26: =הגדרות!B3 | I26: =F26*(1-H26/100)*1.18 | J26: =הגדרות!C3 | K26: =הגדרות!D3 | L26: =I26*(1+J26/100)+K26
A27: קונג (Kong) | B27: קונג כדור ספורט גדול ABS1 | C27: צעצועים | D27: 376000041 | E27: 2026-08 | F27: 33 | G27: 38.94 | H27: =הגדרות!B3 | I27: =F27*(1-H27/100)*1.18 | J27: =הגדרות!C3 | K27: =הגדרות!D3 | L27: =I27*(1+J27/100)+K27
A28: קונג (Kong) | B28: קונג סקוויקר 3 כדורים AST3) S) | C28: צעצועים | D28: 376000054 | E28: 2026-08 | F28: 19 | G28: 22.42 | H28: =הגדרות!B3 | I28: =F28*(1-H28/100)*1.18 | J28: =הגדרות!C3 | K28: =הגדרות!D3 | L28: =I28*(1+J28/100)+K28
A29: קונג (Kong) | B29: קונג צעצוע צפרדע NK11) M/L) | C29: צעצועים | D29: 376000077 | E29: 2026-08 | F29: 63 | G29: 74.34 | H29: =הגדרות!B3 | I29: =F29*(1-H29/100)*1.18 | J29: =הגדרות!C3 | K29: =הגדרות!D3 | L29: =I29*(1+J29/100)+K29
A30: קונג (Kong) | B30: קונג צעצוע אייל (M/L NK14) | C30: צעצועים | D30: 376000083 | E30: 2026-08 | F30: 63 | G30: 74.34 | H30: =הגדרות!B3 | I30: =F30*(1-H30/100)*1.18 | J30: =הגדרות!C3 | K30: =הגדרות!D3 | L30: =I30*(1+J30/100)+K30
A31: קונג (Kong) | B31: קונג צווארון אליזבת רך EL2) M) | C31: צעצועים | D31: 376000097 | E31: 2026-08 | F31: 100 | G31: 118 | H31: =הגדרות!B3 | I31: =F31*(1-H31/100)*1.18 | J31: =הגדרות!C3 | K31: =הגדרות!D3 | L31: =I31*(1+J31/100)+K31
A32: קונג (Kong) | B32: קונג צווארון אליזבת רך EL1) L) | C32: צעצועים | D32: 376000098 | E32: 2026-08 | F32: 124 | G32: 146.32 | H32: =הגדרות!B3 | I32: =F32*(1-H32/100)*1.18 | J32: =הגדרות!C3 | K32: =הגדרות!D3 | L32: =I32*(1+J32/100)+K32
A33: קונג (Kong) | B33: קונג צלחת מעופפת KF15) S) | C33: צעצועים | D33: 376000100 | E33: 2026-08 | F33: 54 | G33: 63.72 | H33: =הגדרות!B3 | I33: =F33*(1-H33/100)*1.18 | J33: =הגדרות!C3 | K33: =הגדרות!D3 | L33: =I33*(1+J33/100)+K33
A34: קונג (Kong) | B34: קונג צעצוע ראקון לעיס עם קשר NKS12, L/M לכלב | C34: צעצועים | D34: 376000135 | E34: 2026-08 | F34: 53 | G34: 62.54 | H34: =הגדרות!B3 | I34: =F34*(1-H34/100)*1.18 | J34: =הגדרות!C3 | K34: =הגדרות!D3 | L34: =I34*(1+J34/100)+K34
A35: קונג (Kong) | B35: קונג גירו SMALL, משחק לחטיפים, PGY3, לכלב | C35: צעצועים | D35: 376000141 | E35: 2026-08 | F35: 57 | G35: 67.26 | H35: =הגדרות!B3 | I35: =F35*(1-H35/100)*1.18 | J35: =הגדרות!C3 | K35: =הגדרות!D3 | L35: =I35*(1+J35/100)+K35
A36: קונג (Kong) | B36: קונג צלחת מעופפת אקסטרים UF3) L) | C36: צעצועים | D36: 376000219 | E36: 2026-08 | F36: 72 | G36: 84.96 | H36: =הגדרות!B3 | I36: =F36*(1-H36/100)*1.18 | J36: =הגדרות!C3 | K36: =הגדרות!D3 | L36: =I36*(1+J36/100)+K36
A37: קונג (Kong) | B37: קונג צלחת מעופפת לגורים KP15) S) | C37: צעצועים | D37: 376000220 | E37: 2026-08 | F37: 61 | G37: 71.98 | H37: =הגדרות!B3 | I37: =F37*(1-H37/100)*1.18 | J37: =הגדרות!C3 | K37: =הגדרות!D3 | L37: =I37*(1+J37/100)+K37
A38: קונג (Kong) | B38: קונג מנשא לבקבוק LF13) L) | C38: אביזרים | D38: 376000225 | E38: 2026-08 | F38: 64 | G38: 75.52 | H38: =הגדרות!B3 | I38: =F38*(1-H38/100)*1.18 | J38: =הגדרות!C3 | K38: =הגדרות!D3 | L38: =I38*(1+J38/100)+K38
A39: קונג (Kong) | B39: קונג קור כדור PFC13 L | C39: צעצועים | D39: 376000283 | E39: 2026-08 | F39: 40 | G39: 47.2 | H39: =הגדרות!B3 | I39: =F39*(1-H39/100)*1.18 | J39: =הגדרות!C3 | K39: =הגדרות!D3 | L39: =I39*(1+J39/100)+K39
A40: קונג (Kong) | B40: קונג ווילד דוב פנים עם חבל NKR5) XS) | C40: צעצועים | D40: 376000314 | E40: 2026-08 | F40: 28 | G40: 33.04 | H40: =הגדרות!B3 | I40: =F40*(1-H40/100)*1.18 | J40: =הגדרות!C3 | K40: =הגדרות!D3 | L40: =I40*(1+J40/100)+K40
...
